Workbook

Sheet 0_Resumen
A1: MODELO EDIFICIO ALICANTE — Resumen ejecutivo
A2: Generado 24/07/2026 por George. Datos reales confirmados + supuestos editables (ver pestaña Inputs).
A4: ⚠️ LEE ESTO PRIMERO
A6: 1) El techo de endeudamiento (35% sobre nómina neta combinada 3.800€) se come casi entero con la NUEVA cuota de San Antonio
A7: tras la ampliación a 230.000€ (pasa de 360€/mes a ~1.150-1.200€/mes, según tipo/plazo reales pendientes de confirmar).
A8: Margen que queda para una hipoteca NUEVA sobre el edificio de Alicante: ver CapacidadDeuda!B7 — es muy poco (revisa el número, es bajo).
A10: 2) Ese cálculo usa SOLO nóminas. Los bancos, en hipotecas de inversión/alquiler, suelen contar un % (50-100%) de la renta
A11: futura estimada como ingreso adicional para el DSTI. SIN verificar esto con el banco, los 3 escenarios pueden parecer
A12: 'no financiables' cuando en la práctica sí lo son. Es la pregunta más importante que tienes que hacerle a tu banco.
A14: 3) OJO: los 230.000€ de la rehipoteca ING que usas aquí como base ya están comprometidos en OTRO plan activo
A15: (compra de vivienda principal en Ibiza: 230k + 130k nueva hipoteca = 360k, dejando solo 100k libres para 2ª operación
A16: con Karina — ver proyectos/busqueda-vivienda/estructura-financiera.md). Si metes los 230k enteros en Alicante,
... A23: CONCLUSIÓN RÁPIDA POR ESCENARIO (fórmulas vivas, se actualizan si cambias Inputs):
A25: Escenario | B25: A (200k interior) | C25: B (275k intermedio) | D25: C (350k capital/costa)
A26: ¿Financiable solo con nóminas? | B26: ='4_Comparativa'!C21 | C26: ='4_Comparativa'!D21 | D26: ='4_Comparativa'!E21
A27: ¿Liquidez rehipoteca cubre fondos propios? | B27: ='4_Comparativa'!C57 | C27: ='4_Comparativa'!D57 | D27: ='4_Comparativa'!E57
A28: Punto de máxima tensión de caja (€) | B28: ='5_Cronograma36m'!I42 | C28: ='5_Cronograma36m'!I85 | D28: ='5_Cronograma36m'!I128
A29: ¿Sobrevive el estrés combinado? | B29: ='6_Estres'!C10 | C29: ='6_Estres'!D10 | D29: ='6_Estres'!E10
A32: ⚠️ RIESGO CRÍTICO (añadido 24/07 v2): el valor de San Antonio (350.000€, BBVA no oficial) usado en este modelo no está confirmado — José Luis ha manejado también 200.000€ en otras conversaciones. La ampliación de 230.000€ solo es coherente con una tasación real de ~330-350k. Si sale más baja, la ampliación completa puede NO ser alcanzable. Ver tabla de sensibilidad en 9_Sensibilidad (fila 'AMPLIACIÓN MÁXIMA TEÓRICA').
A36: RENTABILIDAD NETA vs TIPO LIBRE DE RIESGO (¿compensa el riesgo/obra?)
B37: Escenario A | C37: Escenario B | D37: Escenario C
A38: ¿Bate la alternativa sin riesgo? | B38: ='9_Sensibilidad'!C26 | C38: ='9_Sensibilidad'!D26 | D38: ='9_Sensibilidad'!E26
A40: % de renta que el banco debe contar para hacer financiable cada escenario:
A41: Veredicto por escenario | B41: ='9_Sensibilidad'!C36 | C41: ='9_Sensibilidad'!D36 | D41: ='9_Sensibilidad'!E36
A43: CONCLUSIÓN FINAL — mejor opción de todas las evaluadas:
A44: =IF('7_Decision'!C14>'7_Decision'!D14,"Vivienda principal (retorno 10a "&TEXT('7_Decision'!C14,"#,##0")&"€) gana a Alicante-C (retorno 10a "&TEXT('7_Decision'!D14,"#,##0")&"€). Además, Alicante-C ya sale NO financiable con nóminas — ver 4_Comparativa.","Alicante-C (retorno 10a "&TEXT('7_Decision'!D14,"#,##0")&"€) supera en el papel a vivienda principal (retorno 10a "&TEXT('7_Decision'!C14,"#,##0")&"€), PERO no es ejecutable hoy: no financiable con nóminas y falta liquidez para fondos propios — ver 4_Comparativa.")

Sheet 1_Inputs
A1: INPUTS — datos reales y supuestos de cálculo
A2: Rojo = dato real pendiente de confirmar (no inventado). Amarillo = supuesto editable usado en los cálculos.
A4: DATOS REALES CONFIRMADOS
A5: Nómina neta José Luis (€/mes) — confirmado 24/07/2026 | B5: 2200
A6: Nómina neta Karina (€/mes) — confirmado 24/07/2026 | B6: 1600
A7: Total combinado (€/mes) | B7: =B5+B6
A8: Techo endeudamiento asumido (% ingresos netos, regla DSTI bancaria estándar) | B8: 0.35
A9: Techo endeudamiento (€/mes) | B9: =B7*B8
A11: PISO SAN ANTONIO (Ibiza)
A12: Valor estimado (BBVA, no oficial) | B12: 350000
A13: Tasación oficial (€) — PENDIENTE
A14: Hipoteca viva actual (€) | B14: 60000
A15: Cuota actual (€/mes) | B15: 360
A17: OFERTA AMPLIACIÓN DE CAPITAL (rehipoteca ING)
A18: Importe ampliación (€) — pre-aprobado ING (ver estructura-financiera.md) | B18: 230000
A19: Plazo real de la oferta (años) — PENDIENTE
A20: Tipo interés real de la oferta (%) — PENDIENTE
A21: Estado de la oferta | B21: Pre-aprobada ING — condiciones exactas (plazo/tipo/vinculante por escrito) pendientes de confirmar
A22: ⚠️ Estos 230k están comprometidos en el plan de compra de vivienda principal (230k+130k=360k, dejando 100k libres). Revisar antes de usarlos aquí.
A24: SITUACIÓN LEGAL — IMPAGO SAN ANTONIO
A25: Estado | B25: Burofax enviado 09/07/2026. En plazo de respuesta antes de que Ginés meta el pleito de desahucio.
A27: SUPUESTOS DE CÁLCULO (editables — sólo se usan si dejas en blanco los reales de arriba)
A28: Plazo asumido ampliación (años) | B28: 25
A29: Tipo interés asumido ampliación (%) | B29: 0.035
A30: Comisión cancelación hipoteca actual (%) | B30: 0.005
A31: Gastos tasación ampliación (€) | B31: 400
A32: Gastos notaría ampliación (€) | B32: 700
A33: Gastos registro ampliación (€) | B33: 450
A34: Gestoría ampliación (€) | B34: 300
A35: AJD ampliación Baleares (% s/ importe ampliado) | B35: 0.012
A36: Descuento tasación edificio vacío vs precio (%) | B36: 0.175
A37: LTV máximo edificio inversión (%) | B37: 0.7
A38: Tipo interés hipoteca nueva edificio (%) | B38: 0.0375
A39: Plazo hipoteca nueva edificio (años) | B39: 25
... A53: Duración reforma por planta (meses) | B53: 4
A55: SUPUESTOS ADICIONALES — REVISIÓN 24/07/2026 (v2)
A56: Tipo libre de riesgo, referencia (%) | B56: 0.03
A57: Ingresos mensuales extra (Piticlean/Maia) (€) — PENDIENTE, sin facturar aún
A58: % de esos ingresos extra computable por el banco en DSTI (%) | B58: 0
A59: ¿Banco computa renta futura del alquiler para el DSTI? (%) — PENDIENTE, confirmar con banco | B59: 0
...

Sheet 2_Rehipoteca
A1: REHIPOTECA — liquidez neta real
A3: Importe ampliación (€) | B3: ='1_Inputs'!$B$18
A4: Hipoteca actual a cancelar (€) | B4: ='1_Inputs'!$B$14
A5: Comisión cancelación (€) | B5: =B4*'1_Inputs'!$B$30
A6: Gastos tasación (€) | B6: ='1_Inputs'!$B$31
A7: Gastos notaría (€) | B7: ='1_Inputs'!$B$32
A8: Gastos registro (€) | B8: ='1_Inputs'!$B$33
A9: Gestoría (€) | B9: ='1_Inputs'!$B$34
A10: AJD (%s/importe ampliado) (€) | B10: =(B3-B4)*'1_Inputs'!$B$35
A11: TOTAL GASTOS OPERACIÓN (€) | B11: =SUM(B5:B10)
A12: LIQUIDEZ NETA DISPONIBLE (€) | B12: =B3-B4-B11
A14: Plazo utilizado en el cálculo (años) | B14: =IF('1_Inputs'!$B$19="",'1_Inputs'!$B$28,'1_Inputs'!$B$19)
A15: Tipo interés utilizado (%) | B15: =IF('1_Inputs'!$B$20="",'1_Inputs'!$B$29,'1_Inputs'!$B$20)
A16: CUOTA MENSUAL NUEVA SAN ANTONIO (€) | B16: =PMT(B15/12,B14*12,-B3)
A17: Cuota antigua San Antonio (referencia) (€) | B17: ='1_Inputs'!$B$15
A18: Diferencia mensual (€) | B18: =B16-B17

Sheet 3_CapacidadDeuda
A1: CAPACIDAD DE DEUDA — margen tras San Antonio
A3: Ingresos netos combinados (€/mes) | B3: ='1_Inputs'!$B$7
A4: Techo endeudamiento (%) | B4: ='1_Inputs'!$B$8
A5: TECHO ENDEUDAMIENTO (€/mes) | B5: =B3*B4
A6: Cuota nueva San Antonio (€/mes) | B6: ='2_Rehipoteca'!$B$16
A7: MARGEN DISPONIBLE PARA NUEVA HIPOTECA (€/mes) | B7: =B5-B6
A9: Tipo interés hipoteca nueva edificio (%) | B9: ='1_Inputs'!$B$38
A10: Plazo hipoteca nueva edificio (años) | B10: ='1_Inputs'!$B$39
A11: Capital hipotecable al plazo asumido (€) | B11: =IF(B7<=0,0,PV(B9/12,B10*12,-B7))
A12: Capital hipotecable a 20 años (€) | B12: =IF(B7<=0,0,PV(B9/12,20*12,-B7))
A13: Capital hipotecable a 30 años (€) | B13: =IF(B7<=0,0,PV(B9/12,30*12,-B7))
A15: ⚠️ NOTA: este margen se calcula SOLO con nóminas. En hipotecas de inversión/alquiler, muchos bancos cuentan un % (50-100%) de la renta futura estimada como ingreso adicional para el DSTI. Verifica esto con el banco antes de descartar un escenario solo por este número.

Sheet 4_Comparativa
B1: COMPARATIVA 3 ESCENARIOS — Edificio Alicante
B3: Concepto | C3: Escenario A — Interior (Elche/Novelda/Alcoy/Villena) | D3: Escenario B — Zona intermedia | E3: Escenario C — Capital/Costa Alicante
B4: Precio edificio (€) | C4: 200000 | D4: 275000 | E4: 350000
B5: ITP Comunidad Valenciana (%) | C5: ='1_Inputs'!$B$40 | D5: ='1_Inputs'!$B$40 | E5: ='1_Inputs'!$B$40
B6: ITP (€) | C6: =C4*C5 | D6: =D4*D5 | E6: =E4*E5
B7: Notaría+registro+gestoría (€) | C7: ='1_Inputs'!$B$41 | D7: ='1_Inputs'!$B$41 | E7: ='1_Inputs'!$B$41
B8: TOTAL GASTOS DE COMPRA (€) | C8: =C6+C7 | D8: =D6+D7 | E8: =E6+E7
B9: Descuento tasación edificio vacío (%) | C9: ='1_Inputs'!$B$36 | D9: ='1_Inputs'!$B$36 | E9: ='1_Inputs'!$B$36
B10: Tasación edificio vacío (€) | C10: =C4*(1-C9) | D10: =D4*(1-D9) | E10: =E4*(1-E9)
B11: LTV máximo (%) | C11: ='1_Inputs'!$B$37 | D11: ='1_Inputs'!$B$37 | E11: ='1_Inputs'!$B$37
B12: HIPOTECA MÁXIMA OBTENIBLE (€) | C12: =C10*C11 | D12: =D10*D11 | E12: =E10*E11
B13: FONDOS PROPIOS COMPRA (€) | C13: =C4+C8-C12 | D13: =D4+D8-D12 | E13: =E4+E8-E12
B14: Tipo interés hipoteca edificio (%) | C14: ='1_Inputs'!$B$38 | D14: ='1_Inputs'!$B$38 | E14: ='1_Inputs'!$B$38
B15: Plazo hipoteca edificio (años) | C15: ='1_Inputs'!$B$39 | D15: ='1_Inputs'!$B$39 | E15: ='1_Inputs'!$B$39
B16: CUOTA MENSUAL HIPOTECA EDIFICIO (€) | C16: =PMT(C14/12,C15*12,-C12) | D16: =PMT(D14/12,D15*12,-D12) | E16: =PMT(E14/12,E15*12,-E12)
B17: Cuota nueva San Antonio (€) | C17: ='2_Rehipoteca'!$B$16 | D17: ='2_Rehipoteca'!$B$16 | E17: ='2_Rehipoteca'!$B$16
B18: CUOTA TOTAL MENSUAL COMBINADA (€) | C18: =C16+C17 | D18: =D16+D17 | E18: =E16+E17
B19: Techo endeudamiento (€/mes) | C19: ='3_CapacidadDeuda'!$B$5 | D19: ='3_CapacidadDeuda'!$B$5 | E19: ='3_CapacidadDeuda'!$B$5
B20: Margen (€/mes) | C20: =C19-C18 | D20: =D19-D18 | E20: =E19-E18
B21: ¿FINANCIABLE SOLO CON NÓMINAS? | C21: =IF(C18<=C19,"SÍ","NO — faltan "&TEXT(C18-C19,"#,##0")&"€/mes") | D21: =IF(D18<=D19,"SÍ","NO — faltan "&TEXT(D18-D19,"#,##0")&"€/mes") | E21: =IF(E18<=E19,"SÍ","NO — faltan "&TEXT(E18-E19,"#,##0")&"€/mes")
B23: REFORMA
B24: Nº unidades | C24: ='1_Inputs'!$B$52 | D24: ='1_Inputs'!$B$52 | E24: ='1_Inputs'!$B$52
B25: Superficie por unidad (m²) | C25: ='1_Inputs'!$B$51 | D25: ='1_Inputs'!$B$51 | E25: ='1_Inputs'!$B$51
B26: Coste materiales (€/m²) | C26: ='1_Inputs'!$B$48 | D26: ='1_Inputs'!$B$48 | E26: ='1_Inputs'!$B$48
B27: Coste mano de obra externa (€/m²) | C27: ='1_Inputs'!$B$49 | D27: ='1_Inputs'!$B$49 | E27: ='1_Inputs'!$B$49
B28: Reforma por unidad (€) | C28: =(C26+C27)*C25 | D28: =(D26+D27)*D25 | E28: =(E26+E27)*E25
B29: Proyecto+licencias edificio (€) | C29: ='1_Inputs'!$B$50 | D29: ='1_Inputs'!$B$50 | E29: ='1_Inputs'!$B$50
B30: REFORMA TOTAL EDIFICIO (€) | C30: =C28*C24+C29 | D30: =D28*D24+D29 | E30: =E28*E24+E29
B31: Inversión total (precio+compra+reforma) (€) | C31: =C4+C8+C30 | D31: =D4+D8+D30 | E31: =E4+E8+E30
B32: FONDOS PROPIOS TOTALES NECESARIOS (compra+reforma) (€) | C32: =C13+C30 | D32: =D13+D30 | E32: =E13+E30
B34: RENTABILIDAD
B35: Renta mensual estimada por unidad (€) — editable por zona | C35: 350 | D35: 450 | E35: 600
B36: Renta mensual total edificio (€) | C36: =C35*C24 | D36: =D35*D24 | E36: =E35*E24
B37: Renta anual bruta (€) | C37: =C36*12 | D37: =D36*12 | E37: =E36*12
B38: Vacancia anual (%) | C38: ='1_Inputs'!$B$42 | D38: ='1_Inputs'!$B$42 | E38: ='1_Inputs'!$B$42
B39: Pérdida por vacancia (€) | C39: =C37*C38 | D39: =D37*D38 | E39: =E37*E38
B40: IBI anual total (€) | C40: ='1_Inputs'!$B$43*C24 | D40: ='1_Inputs'!$B$43*D24 | E40: ='1_Inputs'!$B$43*E24
B41: Comunidad anual total (€) | C41: ='1_Inputs'!$B$44*C24 | D41: ='1_Inputs'!$B$44*D24 | E41: ='1_Inputs'!$B$44*E24
B42: Seguros anual total (€) | C42: ='1_Inputs'!$B$45*C24 | D42: ='1_Inputs'!$B$45*D24 | E42: ='1_Inputs'!$B$45*E24
B43: Mantenimiento anual (€) | C43: =C37*'1_Inputs'!$B$46 | D43: =D37*'1_Inputs'!$B$46 | E43: =E37*'1_Inputs'!$B$46
...

Sheet 5_Cronograma36m
B1: CRONOGRAMA DE CAJA — 36 meses, por escenario
B2: Modelo: reforma planta a planta (3 plantas x 2 unidades), secuencial. Caja inicial = fondos propios totales necesarios (compra+reforma) del escenario.
B4: ESCENARIO A — Interior (200.000€)
B5: Mes | C5: Planta activa | D5: Coste reforma mes (€) | E5: Cuota edificio (€) | F5: Cuota San Antonio (€) | G5: Alquiler cobrado (€) | H5: Flujo neto mes (€) | I5: Caja acumulada (€)
B6: 1 | C6: =IF(B6<='1_Inputs'!$B$53,"Planta 1 (obra)",IF(B6<=2*'1_Inputs'!$B$53,"Planta 2 (obra)",IF(B6<=3*'1_Inputs'!$B$53,"Planta 3 (obra)","Completo (alquilado)"))) | D6: =IF(B6<=3*'1_Inputs'!$B$53,(('4_Comparativa'!$C$30-'4_Comparativa'!$C$29)/3)/'1_Inputs'!$B$53,0)+IF(B6=1,'4_Comparativa'!$C$29,0) | E6: ='4_Comparativa'!$C$16 | F6: ='2_Rehipoteca'!$B$16 | G6: =('4_Comparativa'!$C$35*2)*(IF(B6>'1_Inputs'!$B$53,1,0)+IF(B6>2*'1_Inputs'!$B$53,1,0)+IF(B6>3*'1_Inputs'!$B$53,1,0)) | H6: =G6-D6-E6-F6 | I6: ='4_Comparativa'!$C$32+H6
B7: 2 | C7: =IF(B7<='1_Inputs'!$B$53,"Planta 1 (obra)",IF(B7<=2*'1_Inputs'!$B$53,"Planta 2 (obra)",IF(B7<=3*'1_Inputs'!$B$53,"Planta 3 (obra)","Completo (alquilado)"))) | D7: =IF(B7<=3*'1_Inputs'!$B$53,(('4_Comparativa'!$C$30-'4_Comparativa'!$C$29)/3)/'1_Inputs'!$B$53,0)+IF(B7=1,'4_Comparativa'!$C$29,0) | E7: ='4_Comparativa'!$C$16 | F7: ='2_Rehipoteca'!$B$16 | G7: =('4_Comparativa'!$C$35*2)*(IF(B7>'1_Inputs'!$B$53,1,0)+IF(B7>2*'1_Inputs'!$B$53,1,0)+IF(B7>3*'1_Inputs'!$B$53,1,0)) | H7: =G7-D7-E7-F7 | I7: =I6+H7
B8: 3 | C8: =IF(B8<='1_Inputs'!$B$53,"Planta 1 (obra)",IF(B8<=2*'1_Inputs'!$B$53,"Planta 2 (obra)",IF(B8<=3*'1_Inputs'!$B$53,"Planta 3 (obra)","Completo (alquilado)"))) | D8: =IF(B8<=3*'1_Inputs'!$B$53,(('4_Comparativa'!$C$30-'4_Comparativa'!$C$29)/3)/'1_Inputs'!$B$53,0)+IF(B8=1,'4_Comparativa'!$C$29,0) | E8: ='4_Comparativa'!$C$16 | F8: ='2_Rehipoteca'!$B$16 | G8: =('4_Comparativa'!$C$35*2)*(IF(B8>'1_Inputs'!$B$53,1,0)+IF(B8>2*'1_Inputs'!$B$53,1,0)+IF(B8>3*'1_Inputs'!$B$53,1,0)) | H8: =G8-D8-E8-F8 | I8: =I7+H8
B9: 4 | C9: =IF(B9<='1_Inputs'!$B$53,"Planta 1 (obra)",IF(B9<=2*'1_Inputs'!$B$53,"Planta 2 (obra)",IF(B9<=3*'1_Inputs'!$B$53,"Planta 3 (obra)","Completo (alquilado)"))) | D9: =IF(B9<=3*'1_Inputs'!$B$53,(('4_Comparativa'!$C$30-'4_Comparativa'!$C$29)/3)/'1_Inputs'!$B$53,0)+IF(B9=1,'4_Comparativa'!$C$29,0) | E9: ='4_Comparativa'!$C$16 | F9: ='2_Rehipoteca'!$B$16 | G9: =('4_Comparativa'!$C$35*2)*(IF(B9>'1_Inputs'!$B$53,1,0)+IF(B9>2*'1_Inputs'!$B$53,1,0)+IF(B9>3*'1_Inputs'!$B$53,1,0)) | H9: =G9-D9-E9-F9 | I9: =I8+H9
B10: 5 | C10: =IF(B10<='1_Inputs'!$B$53,"Planta 1 (obra)",IF(B10<=2*'1_Inputs'!$B$53,"Planta 2 (obra)",IF(B10<=3*'1_Inputs'!$B$53,"Planta 3 (obra)","Completo (alquilado)"))) | D10: =IF(B10<=3*'1_Inputs'!$B$53,(('4_Comparativa'!$C$30-'4_Comparativa'!$C$29)/3)/'1_Inputs'!$B$53,0)+IF(B10=1,'4_Comparativa'!$C$29,0) | E10: ='4_Comparativa'!$C$16 | F10: ='2_Rehipoteca'!$B$16 | G10: =('4_Comparativa'!$C$35*2)*(IF(B10>'1_Inputs'!$B$53,1,0)+IF(B10>2*'1_Inputs'!$B$53,1,0)+IF(B10>3*'1_Inputs'!$B$53,1,0)) | H10: =G10-D10-E10-F10 | I10: =I9+H10
B11: 6 | C11: =IF(B11<='1_Inputs'!$B$53,"Planta 1 (obra)",IF(B11<=2*'1_Inputs'!$B$53,"Planta 2 (obra)",IF(B11<=3*'1_Inputs'!$B$53,"Planta 3 (obra)","Completo (alquilado)"))) | D11: =IF(B11<=3*'1_Inputs'!$B$53,(('4_Comparativa'!$C$30-'4_Comparativa'!$C$29)/3)/'1_Inputs'!$B$53,0)+IF(B11=1,'4_Comparativa'!$C$29,0) | E11: ='4_Comparativa'!$C$16 | F11: ='2_Rehipoteca'!$B$16 | G11: =('4_Comparativa'!$C$35*2)*(IF(B11>'1_Inputs'!$B$53,1,0)+IF(B11>2*'1_Inputs'!$B$53,1,0)+IF(B11>3*'1_Inputs'!$B$53,1,0)) | H11: =G11-D11-E11-F11 | I11: =I10+H11
B12: 7 | C12: =IF(B12<='1_Inputs'!$B$53,"Planta 1 (obra)",IF(B12<=2*'1_Inputs'!$B$53,"Planta 2 (obra)",IF(B12<=3*'1_Inputs'!$B$53,"Planta 3 (obra)","Completo (alquilado)"))) | D12: =IF(B12<=3*'1_Inputs'!$B$53,(('4_Comparativa'!$C$30-'4_Comparativa'!$C$29)/3)/'1_Inputs'!$B$53,0)+IF(B12=1,'4_Comparativa'!$C$29,0) | E12: ='4_Comparativa'!$C$16 | F12: ='2_Rehipoteca'!$B$16 | G12: =('4_Comparativa'!$C$35*2)*(IF(B12>'1_Inputs'!$B$53,1,0)+IF(B12>2*'1_Inputs'!$B$53,1,0)+IF(B12>3*'1_Inputs'!$B$53,1,0)) | H12: =G12-D12-E12-F12 | I12: =I11+H12
B13: 8 | C13: =IF(B13<='1_Inputs'!$B$53,"Planta 1 (obra)",IF(B13<=2*'1_Inputs'!$B$53,"Planta 2 (obra)",IF(B13<=3*'1_Inputs'!$B$53,"Planta 3 (obra)","Completo (alquilado)"))) | D13: =IF(B13<=3*'1_Inputs'!$B$53,(('4_Comparativa'!$C$30-'4_Comparativa'!$C$29)/3)/'1_Inputs'!$B$53,0)+IF(B13=1,'4_Comparativa'!$C$29,0) | E13: ='4_Comparativa'!$C$16 | F13: ='2_Rehipoteca'!$B$16 | G13: =('4_Comparativa'!$C$35*2)*(IF(B13>'1_Inputs'!$B$53,1,0)+IF(B13>2*'1_Inputs'!$B$53,1,0)+IF(B13>3*'1_Inputs'!$B$53,1,0)) | H13: =G13-D13-E13-F13 | I13: =I12+H13
B14: 9 | C14: =IF(B14<='1_Inputs'!$B$53,"Planta 1 (obra)",IF(B14<=2*'1_Inputs'!$B$53,"Planta 2 (obra)",IF(B14<=3*'1_Inputs'!$B$53,"Planta 3 (obra)","Completo (alquilado)"))) | D14: =IF(B14<=3*'1_Inputs'!$B$53,(('4_Comparativa'!$C$30-'4_Comparativa'!$C$29)/3)/'1_Inputs'!$B$53,0)+IF(B14=1,'4_Comparativa'!$C$29,0) | E14: ='4_Comparativa'!$C$16 | F14: ='2_Rehipoteca'!$B$16 | G14: =('4_Comparativa'!$C$35*2)*(IF(B14>'1_Inputs'!$B$53,1,0)+IF(B14>2*'1_Inputs'!$B$53,1,0)+IF(B14>3*'1_Inputs'!$B$53,1,0)) | H14: =G14-D14-E14-F14 | I14: =I13+H14
B15: 10 | C15: =IF(B15<='1_Inputs'!$B$53,"Planta 1 (obra)",IF(B15<=2*'1_Inputs'!$B$53,"Planta 2 (obra)",IF(B15<=3*'1_Inputs'!$B$53,"Planta 3 (obra)","Completo (alquilado)"))) | D15: =IF(B15<=3*'1_Inputs'!$B$53,(('4_Comparativa'!$C$30-'4_Comparativa'!$C$29)/3)/'1_Inputs'!$B$53,0)+IF(B15=1,'4_Comparativa'!$C$29,0) | E15: ='4_Comparativa'!$C$16 | F15: ='2_Rehipoteca'!$B$16 | G15: =('4_Comparativa'!$C$35*2)*(IF(B15>'1_Inputs'!$B$53,1,0)+IF(B15>2*'1_Inputs'!$B$53,1,0)+IF(B15>3*'1_Inputs'!$B$53,1,0)) | H15: =G15-D15-E15-F15 | I15: =I14+H15
B16: 11 | C16: =IF(B16<='1_Inputs'!$B$53,"Planta 1 (obra)",IF(B16<=2*'1_Inputs'!$B$53,"Planta 2 (obra)",IF(B16<=3*'1_Inputs'!$B$53,"Planta 3 (obra)","Completo (alquilado)"))) | D16: =IF(B16<=3*'1_Inputs'!$B$53,(('4_Comparativa'!$C$30-'4_Comparativa'!$C$29)/3)/'1_Inputs'!$B$53,0)+IF(B16=1,'4_Comparativa'!$C$29,0) | E16: ='4_Comparativa'!$C$16 | F16: ='2_Rehipoteca'!$B$16 | G16: =('4_Comparativa'!$C$35*2)*(IF(B16>'1_Inputs'!$B$53,1,0)+IF(B16>2*'1_Inputs'!$B$53,1,0)+IF(B16>3*'1_Inputs'!$B$53,1,0)) | H16: =G16-D16-E16-F16 | I16: =I15+H16
B17: 12 | C17: =IF(B17<='1_Inputs'!$B$53,"Planta 1 (obra)",IF(B17<=2*'1_Inputs'!$B$53,"Planta 2 (obra)",IF(B17<=3*'1_Inputs'!$B$53,"Planta 3 (obra)","Completo (alquilado)"))) | D17: =IF(B17<=3*'1_Inputs'!$B$53,(('4_Comparativa'!$C$30-'4_Comparativa'!$C$29)/3)/'1_Inputs'!$B$53,0)+IF(B17=1,'4_Comparativa'!$C$29,0) | E17: ='4_Comparativa'!$C$16 | F17: ='2_Rehipoteca'!$B$16 | G17: =('4_Comparativa'!$C$35*2)*(IF(B17>'1_Inputs'!$B$53,1,0)+IF(B17>2*'1_Inputs'!$B$53,1,0)+IF(B17>3*'1_Inputs'!$B$53,1,0)) | H17: =G17-D17-E17-F17 | I17: =I16+H17
B18: 13 | C18: =IF(B18<='1_Inputs'!$B$53,"Planta 1 (obra)",IF(B18<=2*'1_Inputs'!$B$53,"Planta 2 (obra)",IF(B18<=3*'1_Inputs'!$B$53,"Planta 3 (obra)","Completo (alquilado)"))) | D18: =IF(B18<=3*'1_Inputs'!$B$53,(('4_Comparativa'!$C$30-'4_Comparativa'!$C$29)/3)/'1_Inputs'!$B$53,0)+IF(B18=1,'4_Comparativa'!$C$29,0) | E18: ='4_Comparativa'!$C$16 | F18: ='2_Rehipoteca'!$B$16 | G18: =('4_Comparativa'!$C$35*2)*(IF(B18>'1_Inputs'!$B$53,1,0)+IF(B18>2*'1_Inputs'!$B$53,1,0)+IF(B18>3*'1_Inputs'!$B$53,1,0)) | H18: =G18-D18-E18-F18 | I18: =I17+H18
... B41: 36 | C41: =IF(B41<='1_Inputs'!$B$53,"Planta 1 (obra)",IF(B41<=2*'1_Inputs'!$B$53,"Planta 2 (obra)",IF(B41<=3*'1_Inputs'!$B$53,"Planta 3 (obra)","Completo (alquilado)"))) | D41: =IF(B41<=3*'1_Inputs'!$B$53,(('4_Comparativa'!$C$30-'4_Comparativa'!$C$29)/3)/'1_Inputs'!$B$53,0)+IF(B41=1,'4_Comparativa'!$C$29,0) | E41: ='4_Comparativa'!$C$16 | F41: ='2_Rehipoteca'!$B$16 | G41: =('4_Comparativa'!$C$35*2)*(IF(B41>'1_Inputs'!$B$53,1,0)+IF(B41>2*'1_Inputs'!$B$53,1,0)+IF(B41>3*'1_Inputs'!$B$53,1,0)) | H41: =G41-D41-E41-F41 | I41: =I40+H41
B42: PUNTO DE MÁXIMA TENSIÓN DE CAJA (€) | I42: =MIN(I6:I41)
B43: Caja final mes 36 (€) | I43: =I41
B47: ESCENARIO B — Intermedio (275.000€)
B48: Mes | C48: Planta activa | D48: Coste reforma mes (€) | E48: Cuota edificio (€) | F48: Cuota San Antonio (€) | G48: Alquiler cobrado (€) | H48: Flujo neto mes (€) | I48: Caja acumulada (€)
B49: 1 | C49: =IF(B49<='1_Inputs'!$B$53,"Planta 1 (obra)",IF(B49<=2*'1_Inputs'!$B$53,"Planta 2 (obra)",IF(B49<=3*'1_Inputs'!$B$53,"Planta 3 (obra)","Completo (alquilado)"))) | D49: =IF(B49<=3*'1_Inputs'!$B$53,(('4_Comparativa'!$D$30-'4_Comparativa'!$D$29)/3)/'1_Inputs'!$B$53,0)+IF(B49=1,'4_Comparativa'!$D$29,0) | E49: ='4_Comparativa'!$D$16 | F49: ='2_Rehipoteca'!$B$16 | G49: =('4_Comparativa'!$D$35*2)*(IF(B49>'1_Inputs'!$B$53,1,0)+IF(B49>2*'1_Inputs'!$B$53,1,0)+IF(B49>3*'1_Inputs'!$B$53,1,0)) | H49: =G49-D49-E49-F49 | I49: ='4_Comparativa'!$D$32+H49
B50: 2 | C50: =IF(B50<='1_Inputs'!$B$53,"Planta 1 (obra)",IF(B50<=2*'1_Inputs'!$B$53,"Planta 2 (obra)",IF(B50<=3*'1_Inputs'!$B$53,"Planta 3 (obra)","Completo (alquilado)"))) | D50: =IF(B50<=3*'1_Inputs'!$B$53,(('4_Comparativa'!$D$30-'4_Comparativa'!$D$29)/3)/'1_Inputs'!$B$53,0)+IF(B50=1,'4_Comparativa'!$D$29,0) | E50: ='4_Comparativa'!$D$16 | F50: ='2_Rehipoteca'!$B$16 | G50: =('4_Comparativa'!$D$35*2)*(IF(B50>'1_Inputs'!$B$53,1,0)+IF(B50>2*'1_Inputs'!$B$53,1,0)+IF(B50>3*'1_Inputs'!$B$53,1,0)) | H50: =G50-D50-E50-F50 | I50: =I49+H50
B51: 3 | C51: =IF(B51<='1_Inputs'!$B$53,"Planta 1 (obra)",IF(B51<=2*'1_Inputs'!$B$53,"Planta 2 (obra)",IF(B51<=3*'1_Inputs'!$B$53,"Planta 3 (obra)","Completo (alquilado)"))) | D51: =IF(B51<=3*'1_Inputs'!$B$53,(('4_Comparativa'!$D$30-'4_Comparativa'!$D$29)/3)/'1_Inputs'!$B$53,0)+IF(B51=1,'4_Comparativa'!$D$29,0) | E51: ='4_Comparativa'!$D$16 | F51: ='2_Rehipoteca'!$B$16 | G51: =('4_Comparativa'!$D$35*2)*(IF(B51>'1_Inputs'!$B$53,1,0)+IF(B51>2*'1_Inputs'!$B$53,1,0)+IF(B51>3*'1_Inputs'!$B$53,1,0)) | H51: =G51-D51-E51-F51 | I51: =I50+H51
B52: 4 | C52: =IF(B52<='1_Inputs'!$B$53,"Planta 1 (obra)",IF(B52<=2*'1_Inputs'!$B$53,"Planta 2 (obra)",IF(B52<=3*'1_Inputs'!$B$53,"Planta 3 (obra)","Completo (alquilado)"))) | D52: =IF(B52<=3*'1_Inputs'!$B$53,(('4_Comparativa'!$D$30-'4_Comparativa'!$D$29)/3)/'1_Inputs'!$B$53,0)+IF(B52=1,'4_Comparativa'!$D$29,0) | E52: ='4_Comparativa'!$D$16 | F52: ='2_Rehipoteca'!$B$16 | G52: =('4_Comparativa'!$D$35*2)*(IF(B52>'1_Inputs'!$B$53,1,0)+IF(B52>2*'1_Inputs'!$B$53,1,0)+IF(B52>3*'1_Inputs'!$B$53,1,0)) | H52: =G52-D52-E52-F52 | I52: =I51+H52
B53: 5 | C53: =IF(B53<='1_Inputs'!$B$53,"Planta 1 (obra)",IF(B53<=2*'1_Inputs'!$B$53,"Planta 2 (obra)",IF(B53<=3*'1_Inputs'!$B$53,"Planta 3 (obra)","Completo (alquilado)"))) | D53: =IF(B53<=3*'1_Inputs'!$B$53,(('4_Comparativa'!$D$30-'4_Comparativa'!$D$29)/3)/'1_Inputs'!$B$53,0)+IF(B53=1,'4_Comparativa'!$D$29,0) | E53: ='4_Comparativa'!$D$16 | F53: ='2_Rehipoteca'!$B$16 | G53: =('4_Comparativa'!$D$35*2)*(IF(B53>'1_Inputs'!$B$53,1,0)+IF(B53>2*'1_Inputs'!$B$53,1,0)+IF(B53>3*'1_Inputs'!$B$53,1,0)) | H53: =G53-D53-E53-F53 | I53: =I52+H53
B54: 6 | C54: =IF(B54<='1_Inputs'!$B$53,"Planta 1 (obra)",IF(B54<=2*'1_Inputs'!$B$53,"Planta 2 (obra)",IF(B54<=3*'1_Inputs'!$B$53,"Planta 3 (obra)","Completo (alquilado)"))) | D54: =IF(B54<=3*'1_Inputs'!$B$53,(('4_Comparativa'!$D$30-'4_Comparativa'!$D$29)/3)/'1_Inputs'!$B$53,0)+IF(B54=1,'4_Comparativa'!$D$29,0) | E54: ='4_Comparativa'!$D$16 | F54: ='2_Rehipoteca'!$B$16 | G54: =('4_Comparativa'!$D$35*2)*(IF(B54>'1_Inputs'!$B$53,1,0)+IF(B54>2*'1_Inputs'!$B$53,1,0)+IF(B54>3*'1_Inputs'!$B$53,1,0)) | H54: =G54-D54-E54-F54 | I54: =I53+H54
B55: 7 | C55: =IF(B55<='1_Inputs'!$B$53,"Planta 1 (obra)",IF(B55<=2*'1_Inputs'!$B$53,"Planta 2 (obra)",IF(B55<=3*'1_Inputs'!$B$53,"Planta 3 (obra)","Completo (alquilado)"))) | D55: =IF(B55<=3*'1_Inputs'!$B$53,(('4_Comparativa'!$D$30-'4_Comparativa'!$D$29)/3)/'1_Inputs'!$B$53,0)+IF(B55=1,'4_Comparativa'!$D$29,0) | E55: ='4_Comparativa'!$D$16 | F55: ='2_Rehipoteca'!$B$16 | G55: =('4_Comparativa'!$D$35*2)*(IF(B55>'1_Inputs'!$B$53,1,0)+IF(B55>2*'1_Inputs'!$B$53,1,0)+IF(B55>3*'1_Inputs'!$B$53,1,0)) | H55: =G55-D55-E55-F55 | I55: =I54+H55
B56: 8 | C56: =IF(B56<='1_Inputs'!$B$53,"Planta 1 (obra)",IF(B56<=2*'1_Inputs'!$B$53,"Planta 2 (obra)",IF(B56<=3*'1_Inputs'!$B$53,"Planta 3 (obra)","Completo (alquilado)"))) | D56: =IF(B56<=3*'1_Inputs'!$B$53,(('4_Comparativa'!$D$30-'4_Comparativa'!$D$29)/3)/'1_Inputs'!$B$53,0)+IF(B56=1,'4_Comparativa'!$D$29,0) | E56: ='4_Comparativa'!$D$16 | F56: ='2_Rehipoteca'!$B$16 | G56: =('4_Comparativa'!$D$35*2)*(IF(B56>'1_Inputs'!$B$53,1,0)+IF(B56>2*'1_Inputs'!$B$53,1,0)+IF(B56>3*'1_Inputs'!$B$53,1,0)) | H56: =G56-D56-E56-F56 | I56: =I55+H56
B57: 9 | C57: =IF(B57<='1_Inputs'!$B$53,"Planta 1 (obra)",IF(B57<=2*'1_Inputs'!$B$53,"Planta 2 (obra)",IF(B57<=3*'1_Inputs'!$B$53,"Planta 3 (obra)","Completo (alquilado)"))) | D57: =IF(B57<=3*'1_Inputs'!$B$53,(('4_Comparativa'!$D$30-'4_Comparativa'!$D$29)/3)/'1_Inputs'!$B$53,0)+IF(B57=1,'4_Comparativa'!$D$29,0) | E57: ='4_Comparativa'!$D$16 | F57: ='2_Rehipoteca'!$B$16 | G57: =('4_Comparativa'!$D$35*2)*(IF(B57>'1_Inputs'!$B$53,1,0)+IF(B57>2*'1_Inputs'!$B$53,1,0)+IF(B57>3*'1_Inputs'!$B$53,1,0)) | H57: =G57-D57-E57-F57 | I57: =I56+H57
B58: 10 | C58: =IF(B58<='1_Inputs'!$B$53,"Planta 1 (obra)",IF(B58<=2*'1_Inputs'!$B$53,"Planta 2 (obra)",IF(B58<=3*'1_Inputs'!$B$53,"Planta 3 (obra)","Completo (alquilado)"))) | D58: =IF(B58<=3*'1_Inputs'!$B$53,(('4_Comparativa'!$D$30-'4_Comparativa'!$D$29)/3)/'1_Inputs'!$B$53,0)+IF(B58=1,'4_Comparativa'!$D$29,0) | E58: ='4_Comparativa'!$D$16 | F58: ='2_Rehipoteca'!$B$16 | G58: =('4_Comparativa'!$D$35*2)*(IF(B58>'1_Inputs'!$B$53,1,0)+IF(B58>2*'1_Inputs'!$B$53,1,0)+IF(B58>3*'1_Inputs'!$B$53,1,0)) | H58: =G58-D58-E58-F58 | I58: =I57+H58
B59: 11 | C59: =IF(B59<='1_Inputs'!$B$53,"Planta 1 (obra)",IF(B59<=2*'1_Inputs'!$B$53,"Planta 2 (obra)",IF(B59<=3*'1_Inputs'!$B$53,"Planta 3 (obra)","Completo (alquilado)"))) | D59: =IF(B59<=3*'1_Inputs'!$B$53,(('4_Comparativa'!$D$30-'4_Comparativa'!$D$29)/3)/'1_Inputs'!$B$53,0)+IF(B59=1,'4_Comparativa'!$D$29,0) | E59: ='4_Comparativa'!$D$16 | F59: ='2_Rehipoteca'!$B$16 | G59: =('4_Comparativa'!$D$35*2)*(IF(B59>'1_Inputs'!$B$53,1,0)+IF(B59>2*'1_Inputs'!$B$53,1,0)+IF(B59>3*'1_Inputs'!$B$53,1,0)) | H59: =G59-D59-E59-F59 | I59: =I58+H59
B60: 12 | C60: =IF(B60<='1_Inputs'!$B$53,"Planta 1 (obra)",IF(B60<=2*'1_Inputs'!$B$53,"Planta 2 (obra)",IF(B60<=3*'1_Inputs'!$B$53,"Planta 3 (obra)","Completo (alquilado)"))) | D60: =IF(B60<=3*'1_Inputs'!$B$53,(('4_Comparativa'!$D$30-'4_Comparativa'!$D$29)/3)/'1_Inputs'!$B$53,0)+IF(B60=1,'4_Comparativa'!$D$29,0) | E60: ='4_Comparativa'!$D$16 | F60: ='2_Rehipoteca'!$B$16 | G60: =('4_Comparativa'!$D$35*2)*(IF(B60>'1_Inputs'!$B$53,1,0)+IF(B60>2*'1_Inputs'!$B$53,1,0)+IF(B60>3*'1_Inputs'!$B$53,1,0)) | H60: =G60-D60-E60-F60 | I60: =I59+H60
B61: 13 | C61: =IF(B61<='1_Inputs'!$B$53,"Planta 1 (obra)",IF(B61<=2*'1_Inputs'!$B$53,"Planta 2 (obra)",IF(B61<=3*'1_Inputs'!$B$53,"Planta 3 (obra)","Completo (alquilado)"))) | D61: =IF(B61<=3*'1_Inputs'!$B$53,(('4_Comparativa'!$D$30-'4_Comparativa'!$D$29)/3)/'1_Inputs'!$B$53,0)+IF(B61=1,'4_Comparativa'!$D$29,0) | E61: ='4_Comparativa'!$D$16 | F61: ='2_Rehipoteca'!$B$16 | G61: =('4_Comparativa'!$D$35*2)*(IF(B61>'1_Inputs'!$B$53,1,0)+IF(B61>2*'1_Inputs'!$B$53,1,0)+IF(B61>3*'1_Inputs'!$B$53,1,0)) | H61: =G61-D61-E61-F61 | I61: =I60+H61
... B84: 36 | C84: =IF(B84<='1_Inputs'!$B$53,"Planta 1 (obra)",IF(B84<=2*'1_Inputs'!$B$53,"Planta 2 (obra)",IF(B84<=3*'1_Inputs'!$B$53,"Planta 3 (obra)","Completo (alquilado)"))) | D84: =IF(B84<=3*'1_Inputs'!$B$53,(('4_Comparativa'!$D$30-'4_Comparativa'!$D$29)/3)/'1_Inputs'!$B$53,0)+IF(B84=1,'4_Comparativa'!$D$29,0) | E84: ='4_Comparativa'!$D$16 | F84: ='2_Rehipoteca'!$B$16 | G84: =('4_Comparativa'!$D$35*2)*(IF(B84>'1_Inputs'!$B$53,1,0)+IF(B84>2*'1_Inputs'!$B$53,1,0)+IF(B84>3*'1_Inputs'!$B$53,1,0)) | H84: =G84-D84-E84-F84 | I84: =I83+H84
B85: PUNTO DE MÁXIMA TENSIÓN DE CAJA (€) | I85: =MIN(I49:I84)
B86: Caja final mes 36 (€) | I86: =I84
B90: ESCENARIO C — Capital/Costa (350.000€)
B91: Mes | C91: Planta activa | D91: Coste reforma mes (€) | E91: Cuota edificio (€) | F91: Cuota San Antonio (€) | G91: Alquiler cobrado (€) | H91: Flujo neto mes (€) | I91: Caja acumulada (€)
...

Sheet 6_Estres
B1: ESTRÉS — retraso licencia 6m + sobrecoste 25% + vacancia extra
B3: Concepto | C3: Escenario A | D3: Escenario B | E3: Escenario C
B4: Punto de tensión BASE (sin estrés) (€) | C4: ='5_Cronograma36m'!$I$42 | D4: ='5_Cronograma36m'!$I$85 | E4: ='5_Cronograma36m'!$I$128
B5: Impacto retraso licencia 6 meses (€) | C5: =-6*('4_Comparativa'!C16+'2_Rehipoteca'!$B$16) | D5: =-6*('4_Comparativa'!D16+'2_Rehipoteca'!$B$16) | E5: =-6*('4_Comparativa'!E16+'2_Rehipoteca'!$B$16)
B6: Impacto sobrecoste obra 25% (€) | C6: =-('4_Comparativa'!C30*0.25) | D6: =-('4_Comparativa'!D30*0.25) | E6: =-('4_Comparativa'!E30*0.25)
B7: Impacto vacancia extra 1 mes/unidad/año, 3 años (€) | C7: =-('4_Comparativa'!C36*3) | D7: =-('4_Comparativa'!D36*3) | E7: =-('4_Comparativa'!E36*3)
B8: PUNTO DE TENSIÓN COMBINADO (€) | C8: =C4+C5+C6+C7 | D8: =D4+D5+D6+D7 | E8: =E4+E5+E6+E7
B9: Colchón disponible (liquidez rehipoteca no usada en fondos propios) (€) | C9: ='4_Comparativa'!C56-'4_Comparativa'!C32 | D9: ='4_Comparativa'!D56-'4_Comparativa'!D32 | E9: ='4_Comparativa'!E56-'4_Comparativa'!E32
B10: ¿SOBREVIVE EL ESTRÉS COMBINADO? | C10: =IF(C8+C9>=0,"SÍ","NO — faltan "&TEXT(-(C8+C9),"#,##0")&"€") | D10: =IF(D8+D9>=0,"SÍ","NO — faltan "&TEXT(-(D8+D9),"#,##0")&"€") | E10: =IF(E8+E9>=0,"SÍ","NO — faltan "&TEXT(-(E8+E9),"#,##0")&"€")
B12: Metodología: cada impacto se estima como delta directo sobre el punto de tensión base (no se reconstruye un cronograma de 42 meses completo). Es una aproximación transparente, no una simulación exacta mes a mes del escenario de estrés.

Sheet 7_Decision
B1: DECISIÓN — los 230k de ING no pueden ir a los dos sitios
B2: Mejor escenario de alquiler (A/B/C) por rentabilidad neta y payback: Escenario C (350k, capital/costa).
B4: Concepto | C4: Opción 1 — 230k a vivienda principal (Ibiza) | D4: Opción 2 — 230k a edificio Alicante (mejor: Escenario C)
B5: Estructura de financiación | C5: 230k ampliación ING + 130k hipoteca nueva = 360k | D5: 230k ampliación ING (financia parte de fondos propios del edificio)
B6: Cuota ampliación 230k (€/mes) | C6: ='2_Rehipoteca'!$B$16 | D6: ='4_Comparativa'!E16
B7: Cuota hipoteca nueva 130k (€/mes) | C7: =PMT('1_Inputs'!$B$73/12,'1_Inputs'!$B$74*12,-'1_Inputs'!$B$72) | D7: N/A — no hay 2ª hipoteca en esta opción
B8: CUOTA TOTAL VIVIENDA PRINCIPAL (€/mes) | C8: =C6+C7 | D8: ='4_Comparativa'!E18
B9: Alquiler actual que deja de pagar (€/mes) | C9: ='1_Inputs'!$B$61 | D9: N/A
B10: AHORRO/COSTE NETO MENSUAL (€/mes) | C10: =C9-C8 | D10: ='4_Comparativa'!E50
B11: Valor inmueble estimado (€) | C11: ='1_Inputs'!$B$71 | D11: ='4_Comparativa'!E31
B12: Revalorización anual asumida (%) | C12: ='1_Inputs'!$B$70 | D12: ='1_Inputs'!$B$70
B13: RETORNO TOTAL A 5 AÑOS (€) | C13: =C10*60+C11*((1+C12)^5-1) | D13: =D10*60+D11*((1+D12)^5-1)
B14: RETORNO TOTAL A 10 AÑOS (€) | C14: =C10*120+C11*((1+C12)^10-1) | D14: =D10*120+D11*((1+D12)^10-1)
B16: ⚠️ Esta comparación de Opción 2 es teórica: el Escenario C, por sí solo, ya sale NO financiable con solo nóminas y la liquidez no cubre sus fondos propios (ver 4_Comparativa). Sirve para comparar retorno potencial, no significa que la operación esté lista para ejecutar.
B20: CONCLUSIÓN
B21: =IF(C14>D14,"Mejor opción a 10 años: VIVIENDA PRINCIPAL ("&TEXT(C14,"#,##0")&"€ vs Alicante "&TEXT(D14,"#,##0")&"€)","Mejor opción a 10 años: EDIFICIO ALICANTE escenario C ("&TEXT(D14,"#,##0")&"€ vs vivienda principal "&TEXT(C14,"#,##0")&"€)")

Sheet 8_EscenariosDEF
B1: ESCENARIOS D (contado) / E (flip) / F (mixto)
B3: ESCENARIO D — Compra al contado, sin hipoteca nueva (150.000€)
A4: Precio edificio (€) | C4: ='1_Inputs'!$B$62
A5: ITP (€) | C5: =C4*'1_Inputs'!$B$40
A6: Notaría+registro+gestoría (€) | C6: ='1_Inputs'!$B$41
A7: Total gastos de compra (€) | C7: =C5+C6
A8: Reforma por unidad (€) | C8: =('1_Inputs'!$B$48+'1_Inputs'!$B$49)*'1_Inputs'!$B$51
A9: Reforma total edificio (€) | C9: =C8*'1_Inputs'!$B$52+'1_Inputs'!$B$50
B10: FONDOS PROPIOS NECESARIOS — 100% cash (€) | C10: =C4+C7+C9
A11: Liquidez neta disponible (rehipoteca) (€) | C11: ='2_Rehipoteca'!$B$12
B12: ¿LIQUIDEZ CUBRE FONDOS PROPIOS? | C12: =IF(C11>=C10,"SÍ — sobran "&TEXT(C11-C10,"#,##0")&"€","NO — faltan "&TEXT(C10-C11,"#,##0")&"€")
A13: Cuota total mensual (solo San Antonio, sin hipoteca edificio) (€) | C13: ='2_Rehipoteca'!$B$16
A14: Techo endeudamiento (€/mes) | C14: ='3_CapacidadDeuda'!$B$5
B15: ¿ENTRA EN EL TECHO DE ENDEUDAMIENTO? | C15: =IF(C13<=C14,"SÍ","NO")
A16: Renta mensual por unidad asumida (€) | C16: ='1_Inputs'!$B$63
A17: Renta mensual total (€) | C17: =C16*'1_Inputs'!$B$52
A18: Renta anual bruta (€) | C18: =C17*12
A19: Gastos anuales (vacancia+IBI+comunidad+seguros+mantenimiento) (€) | C19: =C18*'1_Inputs'!$B$42+'1_Inputs'!$B$43*'1_Inputs'!$B$52+'1_Inputs'!$B$44*'1_Inputs'!$B$52+'1_Inputs'!$B$45*'1_Inputs'!$B$52+C18*'1_Inputs'!$B$46
A20: Renta neta anual antes IRPF (€) | C20: =C18-C19
A21: IRPF anual (€) | C21: =IF(C20>0,C20*'1_Inputs'!$B$47,0)
B22: CASH FLOW ANUAL NETO (€) — sin cuota de hipoteca de edificio | C22: =C20-C21
A23: Cash flow mensual (€) | C23: =C22/12
A24: Payback fondos propios (años) | C24: =IF(C22>0,C10/C22,"N/A")
B25: Nota: reforma escalonada (unidad a unidad según caja lo permite) — al no haber presión de cuota de hipoteca nueva y sobrar liquidez respecto a fondos propios (ver fila arriba), no hace falta un cronograma mes a mes: la caja disponible cubre la reforma completa desde el principio.
B30: ESCENARIO E — Compra-reforma-VENTA (flip), mismo edificio A/B/C por zona | C30: A (200k interior) | D30: B (275k intermedio) | E30: C (350k capital/costa)
B31: Coste base (compra+gastos+reforma) (€) | C31: ='4_Comparativa'!C31 | D31: ='4_Comparativa'!D31 | E31: ='4_Comparativa'!E31
B32: Precio venta por unidad (€) — editable por zona | C32: ='1_Inputs'!$B$64 | D32: ='1_Inputs'!$B$65 | E32: ='1_Inputs'!$B$66
B33: Ingreso venta total 6 unidades (€) | C33: =C32*'1_Inputs'!$B$52 | D33: =D32*'1_Inputs'!$B$52 | E33: =E32*'1_Inputs'!$B$52
B34: MARGEN BRUTO (€) | C34: =C33-C31 | D34: =D33-D31 | E34: =E33-E31
B35: Plusvalía municipal total (6 unidades) (€) | C35: ='1_Inputs'!$B$67*'1_Inputs'!$B$52 | D35: ='1_Inputs'!$B$67*'1_Inputs'!$B$52 | E35: ='1_Inputs'!$B$67*'1_Inputs'!$B$52
B36: Ganancia patrimonial sujeta a IRPF (€) | C36: =MAX(0,C34-C35) | D36: =MAX(0,D34-D35) | E36: =MAX(0,E34-E35)
B37: IRPF ganancia patrimonial (€) | C37: =C36*'1_Inputs'!$B$68 | D37: =D36*'1_Inputs'!$B$68 | E37: =E36*'1_Inputs'!$B$68
B38: MARGEN NETO (€) | C38: =C34-C35-C37 | D38: =D34-D35-D37 | E38: =E34-E35-E37
B39: Fondos propios invertidos (€) | C39: ='4_Comparativa'!C32 | D39: ='4_Comparativa'!D32 | E39: ='4_Comparativa'!E32
B40: ROI sobre fondos propios (%) | C40: =C38/C39 | D40: =D38/D39 | E40: =E38/E39
B41: Duración obra (meses) | C41: =3*'1_Inputs'!$B$53 | D41: =3*'1_Inputs'!$B$53 | E41: =3*'1_Inputs'!$B$53
B42: Meses comercialización venta | C42: ='1_Inputs'!$B$69 | D42: ='1_Inputs'!$B$69 | E42: ='1_Inputs'!$B$69
B43: Plazo total operación (meses) | C43: =C41+C42 | D43: =D41+D42 | E43: =E41+E42
B44: ROI ANUALIZADO (%) | C44: =(1+C40)^(12/C43)-1 | D44: =(1+D40)^(12/D43)-1 | E44: =(1+E40)^(12/E43)-1
B45: Rentabilidad neta anual alquiler (comparación, Comparativa) (%) | C45: ='4_Comparativa'!C52 | D45: ='4_Comparativa'!D52 | E45: ='4_Comparativa'!E52
...

Sheet 9_Sensibilidad
B1: SENSIBILIDAD — tasación San Antonio, renta, rentabilidad vs riesgo, % DSTI
B3: ⚠️ RIESGO CRÍTICO: el valor de San Antonio usado en 1_Inputs (350.000€, estimación BBVA) no está confirmado. José Luis ha manejado también 200.000€ en otras conversaciones. La ampliación de 230.000€ SOLO es coherente con una tasación oficial de ~330-350k. Tabla de abajo: qué pasa si la tasación oficial sale más baja.
B7: Tasación oficial hipotética (€) | C7: 200000 | D7: 280000 | E7: 300000 | F7: 330000 | G7: 350000
A8: LTV máximo vivienda habitual (%) | C8: ='1_Inputs'!$B$60 | D8: ='1_Inputs'!$B$60 | E8: ='1_Inputs'!$B$60 | F8: ='1_Inputs'!$B$60 | G8: ='1_Inputs'!$B$60
A9: Hipoteca actual a cancelar (€) | C9: ='1_Inputs'!$B$14 | D9: ='1_Inputs'!$B$14 | E9: ='1_Inputs'!$B$14 | F9: ='1_Inputs'!$B$14 | G9: ='1_Inputs'!$B$14
B10: AMPLIACIÓN MÁXIMA TEÓRICA (€) | C10: =C7*C8-C9 | D10: =D7*D8-D9 | E10: =E7*E8-E9 | F10: =F7*F8-F9 | G10: =G7*G8-G9
B11: ¿230.000€ es alcanzable a esta tasación? | C11: =IF(C10>=230000,"SÍ","NO — máximo real "&TEXT(C10,"#,##0")&"€") | D11: =IF(D10>=230000,"SÍ","NO — máximo real "&TEXT(D10,"#,##0")&"€") | E11: =IF(E10>=230000,"SÍ","NO — máximo real "&TEXT(E10,"#,##0")&"€") | F11: =IF(F10>=230000,"SÍ","NO — máximo real "&TEXT(F10,"#,##0")&"€") | G11: =IF(G10>=230000,"SÍ","NO — máximo real "&TEXT(G10,"#,##0")&"€")
B12: Ampliación realista usada (€) | C12: =MAX(0,MIN(230000,C10)) | D12: =MAX(0,MIN(230000,D10)) | E12: =MAX(0,MIN(230000,E10)) | F12: =MAX(0,MIN(230000,F10)) | G12: =MAX(0,MIN(230000,G10))
B13: Comisión cancelación (€) | C13: =C9*'1_Inputs'!$B$30 | D13: =D9*'1_Inputs'!$B$30 | E13: =E9*'1_Inputs'!$B$30 | F13: =F9*'1_Inputs'!$B$30 | G13: =G9*'1_Inputs'!$B$30
B14: AJD sobre importe ampliado realista (€) | C14: =(C12-C9)*'1_Inputs'!$B$35 | D14: =(D12-D9)*'1_Inputs'!$B$35 | E14: =(E12-E9)*'1_Inputs'!$B$35 | F14: =(F12-F9)*'1_Inputs'!$B$35 | G14: =(G12-G9)*'1_Inputs'!$B$35
B15: Otros gastos operación (tasación+notaría+registro+gestoría) (€) | C15: ='1_Inputs'!$B$31+'1_Inputs'!$B$32+'1_Inputs'!$B$33+'1_Inputs'!$B$34 | D15: ='1_Inputs'!$B$31+'1_Inputs'!$B$32+'1_Inputs'!$B$33+'1_Inputs'!$B$34 | E15: ='1_Inputs'!$B$31+'1_Inputs'!$B$32+'1_Inputs'!$B$33+'1_Inputs'!$B$34 | F15: ='1_Inputs'!$B$31+'1_Inputs'!$B$32+'1_Inputs'!$B$33+'1_Inputs'!$B$34 | G15: ='1_Inputs'!$B$31+'1_Inputs'!$B$32+'1_Inputs'!$B$33+'1_Inputs'!$B$34
B16: LIQUIDEZ NETA RESULTANTE (€) | C16: =C12-C9-C13-C14-C15 | D16: =D12-D9-D13-D14-D15 | E16: =E12-E9-E13-E14-E15 | F16: =F12-F9-F13-F14-F15 | G16: =G12-G9-G13-G14-G15
B17: CUOTA MENSUAL RESULTANTE (€) | C17: =IF(C12<=0,0,PMT('2_Rehipoteca'!$B$15/12,'2_Rehipoteca'!$B$14*12,-C12)) | D17: =IF(D12<=0,0,PMT('2_Rehipoteca'!$B$15/12,'2_Rehipoteca'!$B$14*12,-D12)) | E17: =IF(E12<=0,0,PMT('2_Rehipoteca'!$B$15/12,'2_Rehipoteca'!$B$14*12,-E12)) | F17: =IF(F12<=0,0,PMT('2_Rehipoteca'!$B$15/12,'2_Rehipoteca'!$B$14*12,-F12)) | G17: =IF(G12<=0,0,PMT('2_Rehipoteca'!$B$15/12,'2_Rehipoteca'!$B$14*12,-G12))
B19: Caso base actual del modelo = columna 350.000€ (coincide con 2_Rehipoteca).
B22: RENTABILIDAD NETA vs TIPO LIBRE DE RIESGO
B23: Concepto | C23: Escenario A | D23: Escenario B | E23: Escenario C
A24: Rentabilidad neta (%) | C24: ='4_Comparativa'!C52 | D24: ='4_Comparativa'!D52 | E24: ='4_Comparativa'!E52
A25: Tipo libre de riesgo (%) | C25: ='1_Inputs'!$B$56 | D25: ='1_Inputs'!$B$56 | E25: ='1_Inputs'!$B$56
B26: ¿Bate la alternativa sin riesgo? | C26: =IF(C24>C25,"SÍ","NO") | D26: =IF(D24>D25,"SÍ","NO") | E26: =IF(E24>E25,"SÍ","NO")
B29: % DE RENTA FUTURA QUE EL BANCO TENDRÍA QUE CONTAR PARA HACER FINANCIABLE CADA ESCENARIO
B30: Concepto | C30: Escenario A | D30: Escenario B | E30: Escenario C
A31: Cuota total mensual combinada (€) | C31: ='4_Comparativa'!C18 | D31: ='4_Comparativa'!D18 | E31: ='4_Comparativa'!E18
A32: Ingresos nómina combinados (€) | C32: ='1_Inputs'!$B$7 | D32: ='1_Inputs'!$B$7 | E32: ='1_Inputs'!$B$7
A33: Renta mensual del edificio (€) | C33: ='4_Comparativa'!C36 | D33: ='4_Comparativa'!D36 | E33: ='4_Comparativa'!E36
A34: Techo endeudamiento (%) | C34: ='1_Inputs'!$B$8 | D34: ='1_Inputs'!$B$8 | E34: ='1_Inputs'!$B$8
B35: % MÍNIMO DE RENTA QUE EL BANCO DEBE CONTAR | C35: =MAX(0,(C31/C34-C32)/C33) | D35: =MAX(0,(D31/D34-D32)/D33) | E35: =MAX(0,(E31/E34-E32)/E33)
B36: Veredicto | C36: =IF(C35<=0,"Ya financiable sin contar renta",IF(C35<=1,"Necesita que el banco cuente "&TEXT(C35,"0%")&" de la renta","Ni contando el 100% de la renta es financiable")) | D36: =IF(D35<=0,"Ya financiable sin contar renta",IF(D35<=1,"Necesita que el banco cuente "&TEXT(D35,"0%")&" de la renta","Ni contando el 100% de la renta es financiable")) | E36: =IF(E35<=0,"Ya financiable sin contar renta",IF(E35<=1,"Necesita que el banco cuente "&TEXT(E35,"0%")&" de la renta","Ni contando el 100% de la renta es financiable"))
B39: SENSIBILIDAD DE RENTA — cash flow anual y payback, por escenario de precio
B40: La renta de 350€/unidad en interior está sin validar. Tabla: qué pasa con cash flow y payback si la renta real es distinta.
B41: Escenario A (200k)
B42: Renta €/unidad | C42: Cash flow anual (€) | D42: Cash flow mensual (€) | E42: Payback (años)
B43: 300 | C43: =((300*'4_Comparativa'!$C$24*12)-((300*'4_Comparativa'!$C$24*12)*'1_Inputs'!$B$42+(300*'4_Comparativa'!$C$24*12)*'1_Inputs'!$B$46+'4_Comparativa'!$C$40+'4_Comparativa'!$C$41+'4_Comparativa'!$C$42))-(MAX(0,((300*'4_Comparativa'!$C$24*12)-((300*'4_Comparativa'!$C$24*12)*'1_Inputs'!$B$42+(300*'4_Comparativa'!$C$24*12)*'1_Inputs'!$B$46+'4_Comparativa'!$C$40+'4_Comparativa'!$C$41+'4_Comparativa'!$C$42))*'1_Inputs'!$B$47))-'4_Comparativa'!$C$48 | D43: =C43/12 | E43: =IF(C43>0,'4_Comparativa'!$C$32/C43,"N/A")
B44: 350 | C44: =((350*'4_Comparativa'!$C$24*12)-((350*'4_Comparativa'!$C$24*12)*'1_Inputs'!$B$42+(350*'4_Comparativa'!$C$24*12)*'1_Inputs'!$B$46+'4_Comparativa'!$C$40+'4_Comparativa'!$C$41+'4_Comparativa'!$C$42))-(MAX(0,((350*'4_Comparativa'!$C$24*12)-((350*'4_Comparativa'!$C$24*12)*'1_Inputs'!$B$42+(350*'4_Comparativa'!$C$24*12)*'1_Inputs'!$B$46+'4_Comparativa'!$C$40+'4_Comparativa'!$C$41+'4_Comparativa'!$C$42))*'1_Inputs'!$B$47))-'4_Comparativa'!$C$48 | D44: =C44/12 | E44: =IF(C44>0,'4_Comparativa'!$C$32/C44,"N/A")
B45: 400 | C45: =((400*'4_Comparativa'!$C$24*12)-((400*'4_Comparativa'!$C$24*12)*'1_Inputs'!$B$42+(400*'4_Comparativa'!$C$24*12)*'1_Inputs'!$B$46+'4_Comparativa'!$C$40+'4_Comparativa'!$C$41+'4_Comparativa'!$C$42))-(MAX(0,((400*'4_Comparativa'!$C$24*12)-((400*'4_Comparativa'!$C$24*12)*'1_Inputs'!$B$42+(400*'4_Comparativa'!$C$24*12)*'1_Inputs'!$B$46+'4_Comparativa'!$C$40+'4_Comparativa'!$C$41+'4_Comparativa'!$C$42))*'1_Inputs'!$B$47))-'4_Comparativa'!$C$48 | D45: =C45/12 | E45: =IF(C45>0,'4_Comparativa'!$C$32/C45,"N/A")
B46: 450 | C46: =((450*'4_Comparativa'!$C$24*12)-((450*'4_Comparativa'!$C$24*12)*'1_Inputs'!$B$42+(450*'4_Comparativa'!$C$24*12)*'1_Inputs'!$B$46+'4_Comparativa'!$C$40+'4_Comparativa'!$C$41+'4_Comparativa'!$C$42))-(MAX(0,((450*'4_Comparativa'!$C$24*12)-((450*'4_Comparativa'!$C$24*12)*'1_Inputs'!$B$42+(450*'4_Comparativa'!$C$24*12)*'1_Inputs'!$B$46+'4_Comparativa'!$C$40+'4_Comparativa'!$C$41+'4_Comparativa'!$C$42))*'1_Inputs'!$B$47))-'4_Comparativa'!$C$48 | D46: =C46/12 | E46: =IF(C46>0,'4_Comparativa'!$C$32/C46,"N/A")
B47: 500 | C47: =((500*'4_Comparativa'!$C$24*12)-((500*'4_Comparativa'!$C$24*12)*'1_Inputs'!$B$42+(500*'4_Comparativa'!$C$24*12)*'1_Inputs'!$B$46+'4_Comparativa'!$C$40+'4_Comparativa'!$C$41+'4_Comparativa'!$C$42))-(MAX(0,((500*'4_Comparativa'!$C$24*12)-((500*'4_Comparativa'!$C$24*12)*'1_Inputs'!$B$42+(500*'4_Comparativa'!$C$24*12)*'1_Inputs'!$B$46+'4_Comparativa'!$C$40+'4_Comparativa'!$C$41+'4_Comparativa'!$C$42))*'1_Inputs'!$B$47))-'4_Comparativa'!$C$48 | D47: =C47/12 | E47: =IF(C47>0,'4_Comparativa'!$C$32/C47,"N/A")
B48: 550 | C48: =((550*'4_Comparativa'!$C$24*12)-((550*'4_Comparativa'!$C$24*12)*'1_Inputs'!$B$42+(550*'4_Comparativa'!$C$24*12)*'1_Inputs'!$B$46+'4_Comparativa'!$C$40+'4_Comparativa'!$C$41+'4_Comparativa'!$C$42))-(MAX(0,((550*'4_Comparativa'!$C$24*12)-((550*'4_Comparativa'!$C$24*12)*'1_Inputs'!$B$42+(550*'4_Comparativa'!$C$24*12)*'1_Inputs'!$B$46+'4_Comparativa'!$C$40+'4_Comparativa'!$C$41+'4_Comparativa'!$C$42))*'1_Inputs'!$B$47))-'4_Comparativa'!$C$48 | D48: =C48/12 | E48: =IF(C48>0,'4_Comparativa'!$C$32/C48,"N/A")
B51: Escenario B (275k)
B52: Renta €/unidad | C52: Cash flow anual (€) | D52: Cash flow mensual (€) | E52: Payback (años)
B53: 300 | C53: =((300*'4_Comparativa'!$D$24*12)-((300*'4_Comparativa'!$D$24*12)*'1_Inputs'!$B$42+(300*'4_Comparativa'!$D$24*12)*'1_Inputs'!$B$46+'4_Comparativa'!$D$40+'4_Comparativa'!$D$41+'4_Comparativa'!$D$42))-(MAX(0,((300*'4_Comparativa'!$D$24*12)-((300*'4_Comparativa'!$D$24*12)*'1_Inputs'!$B$42+(300*'4_Comparativa'!$D$24*12)*'1_Inputs'!$B$46+'4_Comparativa'!$D$40+'4_Comparativa'!$D$41+'4_Comparativa'!$D$42))*'1_Inputs'!$B$47))-'4_Comparativa'!$D$48 | D53: =C53/12 | E53: =IF(C53>0,'4_Comparativa'!$D$32/C53,"N/A")
...
